<robot name="onshape">
<link name="torso">
<visual>
<origin xyz="0 0 0" rpy="0 -0 0" />
<geometry>
<mesh filename="../meshs/torso.stl"/>
</geometry>
<material name="torso_material">
<color rgba="0.91764705882352937127 0.91764705882352937127 0.91764705882352937127 1.0"/>
</material>
</visual>
<!-- Shapes for torso -->
<collision>
<origin xyz="0.020000000000000000416 0 0.11999999999999999556" rpy="0 -0 0" />
<geometry>
<box size="0.17999999999999999334 0.25 0.25" />
</geometry>
</collision>
<inertial>
<origin xyz="0.012329400000000033735 -0.0023557000000000078745 0.11404699999999998172" rpy="0 0 0"/>
<mass value="5.378118099999987578" />
<inertia ixx="0.089876431045178117873" ixy="-0.0012036644711563740211"  ixz="-0.00038411829254754816833" iyy="0.081725438039230421938" iyz="0.00060976296589066163612" izz="0.05304158706118268507" />
</inertial>
</link>

<link name="ll_hr">
<visual>
<origin xyz="8.3411161867551695001e-17 -0.069999999999999854006 1.5210270693501456768e-16" rpy="-4.7960273332227889665e-28 -0.78539816339744961127 -2.5931996357134510914e-31" />
<geometry>
<mesh filename="../meshs/ll_hr.stl"/>
</geometry>
<material name="ll_hr_material">
<color rgba="0.91764705882352937127 0.91764705882352937127 0.91764705882352937127 1.0"/>
</material>
</visual>
<!-- Shapes for ll_hr -->
<inertial>
<origin xyz="-0.0071750125087001563606 0.00063800000000002743406 -0.060329643464054769075" rpy="0 0 0"/>
<mass value="0.7970000000000008189" />
<inertia ixx="0.0016406343011190645514" ixy="4.2346623516963226985e-06"  ixz="-0.00011521182091135505213" iyy="0.0012484152851109599127" iyz="5.8764351819077158761e-06" izz="0.00078961357000411312723" />
</inertial>
</link>

<link name="ll_haa">
<visual>
<origin xyz="0.064999999999999572009 -0.069999999999999742983 0.015799999999995966576" rpy="4.2166986512874552266e-15 0.785398163397448279 5.1233902195250893073e-31" />
<geometry>
<mesh filename="../meshs/ll_haa.stl"/>
</geometry>
<material name="ll_haa_material">
<color rgba="0.91764705882352937127 0.91764705882352937127 0.91764705882352937127 1.0"/>
</material>
</visual>
<!-- Shapes for ll_haa -->
<!-- <collision>
<origin xyz="6.7798497201468355122e-05 -0.014999999999999319433 -0.064931795421634352916" rpy="1.5707963267949007768 0.785398163397448279 5.1233902195250893073e-31" />
<geometry>
<cylinder length="0.050000000000000002776" radius="0.055000000000000000278" />
</geometry>
</collision> -->
<inertial>
<origin xyz="0.00060661386446610177092 -0.0097349999999993917094 -0.061109176162539427524" rpy="0 0 0"/>
<mass value="0.89699999999999757705" />
<inertia ixx="0.0014612661065417926597" ixy="-9.508658014417258874e-07"  ixz="4.9263169120500148587e-06" iyy="0.0018641696668689586476" iyz="-0.00015708831652932371829" izz="0.00094931186312992559689" />
</inertial>
</link>

<link name="ll_hfe">
<visual>
<origin xyz="0.10309616869699468611 -0.011172287142745998545 -0.085799999999994921995" rpy="1.5707963267949038855 1.74899230643811231e-14 1.570796326794896558" />
<geometry>
<mesh filename="../meshs/ll_hfe.stl"/>
</geometry>
<material name="ll_hfe_material">
<color rgba="0.91764705882352937127 0.91764705882352937127 0.91764705882352937127 1.0"/>
</material>
</visual>
<!-- Shapes for ll_hfe -->
<collision>
<origin xyz="9.6168696995690972074e-05 -2.8714274354774138587e-07 0.054200000000005646439" rpy="-3.1415926535897860106 1.74899230643811231e-14 1.570796326794896558" />
<geometry>
<cylinder length="0.089999999999999996669" radius="0.061499999999999999112" />
</geometry>
</collision>
<collision>
<origin xyz="-0.11490383130300428627 -2.8714274346100521207e-07 0.059200000000006428036" rpy="-3.1415926535897860106 1.74899230643811231e-14 1.570796326794896558" />
<geometry>
<cylinder length="0.080000000000000001665" radius="0.051999999999999997613" />
</geometry>
</collision>
<inertial>
<origin xyz="-0.059699831303004283201 -0.00099928714274370375459 0.04547300000000603637" rpy="0 0 0"/>
<mass value="2.6890000000000013891" />
<inertia ixx="0.0059944464330809786937" ixy="0.00019079100061922965332"  ixz="0.0014556175188272181455" iyy="0.018188324559920514972" iyz="-5.4409777543802354427e-05" izz="0.018978215894452029472" />
</inertial>
</link>

<link name="ll_kfe">
<visual>
<origin xyz="0.3230961686969961999 -0.011172287143240726068 -0.15999999999999256484" rpy="1.5707963267948958919 -1.8203544808569294933e-14 1.570796326794896558" />
<geometry>
<mesh filename="../meshs/ll_kfe.stl"/>
</geometry>
<material name="ll_kfe_material">
<color rgba="0.91764705882352937127 0.91764705882352937127 0.91764705882352937127 1.0"/>
</material>
</visual>
<!-- Shapes for ll_kfe -->
<collision>
<origin xyz="-0.056903831303003915565 -0.0011722871432436384603 7.3274719625260331668e-15" rpy="1.5707963267948958919 -1.8203544808569294933e-14 1.570796326794896558" />
<geometry>
<box size="0.02999999999999999889 0.040000000000000000833 0.16000000000000000333" />
</geometry>
</collision>
<inertial>
<origin xyz="-0.085694831303003926593 -0.009280287143243599185 -0.0022319999999928182878" rpy="0 0 0"/>
<mass value="0.3499999999999999778" />
<inertia ixx="0.00010850320647079418472" ixy="-0.00013018330729977633403"  ixz="-8.4279113636776882454e-06" iyy="0.0015842167893813238148" iyz="-4.6628317965192898483e-06" izz="0.0016101360290329644765" />
</inertial>
</link>

<link name="ll_ffe">
<visual>
<origin xyz="0.50309616869699824715 -0.011172287143647298413 -0.15999999999998817946" rpy="1.5707963267948958919 -1.8203544808569294933e-14 1.570796326794896558" />
<geometry>
<mesh filename="../meshs/ll_ffe.stl"/>
</geometry>
<material name="ll_ffe_material">
<color rgba="0.91764705882352937127 0.91764705882352937127 0.91764705882352937127 1.0"/>
</material>
</visual>
<!-- Shapes for ll_ffe -->
<inertial>
<origin xyz="-0.0010781713030018069688 0.023770712856349782149 6.8000000012059254968e-05" rpy="0 0 0"/>
<mass value="0.099322750000000056825" />
<inertia ixx="7.6220307054554564913e-05" ixy="-1.2169715047253270242e-05"  ixz="2.7666933550945111434e-07" iyy="1.1575849952207155593e-05" iyz="9.1677779895007629252e-07" izz="8.2015105811780541047e-05" />
</inertial>
</link>

<link name="ll_faa">
<visual>
<origin xyz="-0.15999999999998909539 0.50309616869699735897 -0.028672287143649135416" rpy="-1.570796326794896558 -1.570796326794896558 0" />
<geometry>
<mesh filename="../meshs/ll_faa.stl"/>
</geometry>
<material name="ll_faa_material">
<color rgba="0.91764705882352937127 0.91764705882352937127 0.91764705882352937127 1.0"/>
</material>
</visual>
<!-- Shapes for ll_faa -->
<collision>
<origin xyz="1.090794121694216301e-14 -0.042903831303002681885 0.013327712856350867193" rpy="-3.141592653589793116 -1.3962636194521678146 1.570796326794896558" />
<geometry>
<box size="0.16000000000000000333 0.055000000000000000278 0.01200000000000000025" />
</geometry>
</collision>
<!-- <collision>
<origin xyz="1.090794121694216301e-14 9.6168696997356306611e-05 0.038827712856350865556" rpy="-3.141592653589793116 -6.520241754503373831e-42 1.570796326794896558" />
<geometry>
<cylinder length="0.06500000000000000222" radius="0.026999999999999999695" />
</geometry>
</collision> -->
<inertial>
<origin xyz="-2.8999999989176572512e-05 -0.016397831303002541325 0.015338712856350831398" rpy="0 0 0"/>
<mass value="0.50700000000000067235" />
<inertia ixx="0.0010941972153327909727" ixy="1.2622581346702725591e-06"  ixz="3.5182387734493031009e-06" iyy="0.0009101859819928102965" iyz="-0.00019146081159969580133" izz="0.00044396659684889345316" />
</inertial>
</link>

<link name="LL_FOOT">
<inertial>
<origin xyz="0 0 0" rpy="0 0 0" />
<mass value="1e-9" />
<inertia ixx="0" ixy="0" ixz="0" iyy="0" iyz="0" izz="0" />
</inertial>
</link>
<joint name="LL_FOOT_frame" type="fixed">
<origin xyz="5.8564264548977007507e-15 -0.048688979881312266507 0.014485028526583749314" rpy="3.141592653589793116 -1.3962634015954653588 1.570796326794896558" />
<parent link="ll_faa" />
<child link="LL_FOOT" />
<axis xyz="0 0 0"/>
</joint>

<joint name="LL_FAA" type="revolute">
<origin xyz="-3.6637359812630165834e-15 0.017499999999998770012 -3.8857805861880478915e-16" rpy="-1.5707963267948938935 -1.5707963267948830133 0" />
<parent link="ll_ffe" />
<child link="ll_faa" />
<axis xyz="0 0 1"/>
<limit effort="5" velocity="42" lower="-0.52359877559829881566" upper="0.52359877559829881566"/>
<joint_properties friction="0.0"/>
</joint>

<joint name="LL_FFE" type="revolute">
<origin xyz="-0.18000000000000221378 4.0657234523511220914e-13 -4.4131365228849972482e-15" rpy="1.1476240689710679376e-27 8.5046658791676055396e-29 8.3266726846923028133e-17" />
<parent link="ll_kfe" />
<child link="ll_ffe" />
<axis xyz="0 0 1"/>
<limit effort="20" velocity="20" lower="-0.52359877559829881566" upper="0.69813170079773179122"/>
<joint_properties friction="0.0"/>
</joint>

<joint name="LL_KFE" type="revolute">
<origin xyz="-0.21999999999999989009 5.0031506715342288771e-13 0.074199999999999918798" rpy="-3.6817022053377870126e-14 8.7267374499327085356e-15 1.9428902930912523323e-16" />
<parent link="ll_hfe" />
<child link="ll_kfe" />
<axis xyz="0 0 1"/>
<limit effort="30" velocity="14" lower="0" upper="2.0943951023931952626"/>
<joint_properties friction="0.0"/>
</joint>

<joint name="LL_HFE" type="revolute">
<origin xyz="2.6367796834847467835e-16 0.015799999999994956967 -0.064999999999999530376" rpy="-1.5707963267948812369 -0.78539816339744850104 7.0425066851191171402e-15" />
<parent link="ll_haa" />
<child link="ll_hfe" />
<axis xyz="0 0 1"/>
<limit effort="30" velocity="20" lower="-1.7453292519943295336" upper="0.52359877559829881566"/>
<joint_properties friction="0.0"/>
</joint>

<joint name="LL_HAA" type="revolute">
<origin xyz="0.015799999999996268418 -2.7755575615628913511e-16 -0.064999999999999849565" rpy="-3.9874966918901588628e-15 -1.5707963267948950037 0" />
<parent link="ll_hr" />
<child link="ll_haa" />
<axis xyz="0 0 1"/>
<limit effort="20" velocity="23" lower="-0.61086523819801530344" upper="0.61086523819801530344"/>
<joint_properties friction="0.0"/>
</joint>

<joint name="LL_HR" type="revolute">
<origin xyz="-1.6653345369377348106e-16 0.069999999999999854006 -4.8572257327350610969e-17" rpy="4.2686888720530165754e-16 0.78539816339746193474 2.380040609040672766e-15" />
<parent link="torso" />
<child link="ll_hr" />
<axis xyz="0 0 1"/>
<limit effort="20" velocity="23" lower="-0.61086523819801530344" upper="0.61086523819801530344"/>
<joint_properties friction="0.0"/>
</joint>

<link name="lr_hr">
<visual>
<origin xyz="9.8130778667825160077e-17 0.070000000000000062172 1.7663540160183579609e-16" rpy="-1.80256122170187935e-27 -0.7853981633974492782 -1.8367624050141598029e-31" />
<geometry>
<mesh filename="../meshs/lr_hr.stl"/>
</geometry>
<material name="lr_hr_material">
<color rgba="0.91764705882352937127 0.91764705882352937127 0.91764705882352937127 1.0"/>
</material>
</visual>
<!-- Shapes for lr_hr -->
<inertial>
<origin xyz="-0.0071750125087001589627 -0.00063800000000023560087 -0.060329643464055830726" rpy="0 0 0"/>
<mass value="0.79699999999999693312" />
<inertia ixx="0.0016409930094170518695" ixy="8.0630526667213361863e-07"  ixz="-0.00011521182091140817804" iyy="0.0012484152851109570938" iyz="-4.3689717945135577451e-06" izz="0.00078997227830219000043" />
</inertial>
</link>

<link name="lr_haa">
<visual>
<origin xyz="0.064999999999999585887 0.070000000000000159317 0.015799999999996452299" rpy="3.365885708303340778e-15 0.78539816339744861207 1.2683748906114756047e-31" />
<geometry>
<mesh filename="../meshs/lr_haa.stl"/>
</geometry>
<material name="lr_haa_material">
<color rgba="0.91764705882352937127 0.91764705882352937127 0.91764705882352937127 1.0"/>
</material>
</visual>
<!-- Shapes for lr_haa -->
<!-- <collision>
<origin xyz="6.779849720116304379e-05 0.015000000000000505984 -0.064931795421634158627" rpy="1.5707963267948998887 0.78539816339744861207 1.2683748906114756047e-31" />
<geometry>
<cylinder length="0.050000000000000002776" radius="0.055000000000000000278" />
</geometry>
</collision> -->
<inertial>
<origin xyz="0.00060661386446551890383 0.0097350000000009546952 -0.061109176162539420585" rpy="0 0 0"/>
<mass value="0.89700000000000745803" />
<inertia ixx="0.0014661274494049468618" ixy="-9.7460256768142710017e-08"  ixz="1.2006374236349762426e-06" iyy="0.0018651290713510967813" iyz="0.00015962052014566310626" izz="0.00094540985323500372883" />
</inertial>
</link>

<link name="lr_hfe">
<visual>
<origin xyz="0.10309616869699547714 -0.011172287142743415542 0.085800000000000278821" rpy="1.5707963267948978903 2.4663018163742551871e-15 1.570796326794896558" />
<geometry>
<mesh filename="../meshs/lr_hfe.stl"/>
</geometry>
<material name="lr_hfe_material">
<color rgba="0.91764705882352937127 0.91764705882352937127 0.91764705882352937127 1.0"/>
</material>
</visual>
<!-- Shapes for lr_hfe -->
<collision>
<origin xyz="9.6168696995316271803e-05 -2.8714274375937764994e-07 -0.054199999999999623479" rpy="-3.1415926535897922278 2.4663018163742551871e-15 1.570796326794896558" />
<geometry>
<cylinder length="0.089999999999999996669" radius="0.061499999999999999112" />
</geometry>
</collision>
<collision>
<origin xyz="-0.11490383130300468872 -2.8714274377152071427e-07 -0.059199999999999461386" rpy="-3.1415926535897922278 2.4663018163742551871e-15 1.570796326794896558" />
<geometry>
<cylinder length="0.080000000000000001665" radius="0.051999999999999997613" />
</geometry>
</collision>
<inertial>
<origin xyz="-0.059699831303004546879 -0.00099928714274374538795 -0.045472999999999409726" rpy="0 0 0"/>
<mass value="2.6890000000000005009" />
<inertia ixx="0.0059944093540668071454" ixy="0.00019189741544671393234"  ixz="-0.0014560673148697135439" iyy="0.018186321637810375779" iyz="5.4856004218848921283e-05" izz="0.018976154384902375882" />
</inertial>
</link>

<link name="lr_kfe">
<visual>
<origin xyz="0.32309616869699464559 -0.011172287142751816807 0.16000000000000005884" rpy="1.570796326794896558 2.0387620342698703042e-30 1.570796326794896558" />
<geometry>
<mesh filename="../meshs/lr_kfe.stl"/>
</geometry>
<material name="lr_kfe_material">
<color rgba="0.91764705882352937127 0.91764705882352937127 0.91764705882352937127 1.0"/>
</material>
</visual>
<!-- Shapes for lr_kfe -->
<collision>
<origin xyz="-0.056903831303005469877 -0.0011722871427518165993 5.5511151231257827021e-17" rpy="1.570796326794896558 2.0387620342698703042e-30 1.570796326794896558" />
<geometry>
<box size="0.02999999999999999889 0.040000000000000000833 0.16000000000000000333" />
</geometry>
</collision>
<inertial>
<origin xyz="-0.085694831303005480905 -0.0092802871427518172226 0.002232000000000039508" rpy="0 0 0"/>
<mass value="0.3499999999999999778" />
<inertia ixx="0.00010850319312452964794" ixy="-0.00013018331822973311634"  ixz="8.4281249094896539442e-06" iyy="0.0015842167725954475234" iyz="4.6628220175844334544e-06" izz="0.0016101360242463363514" />
</inertial>
</link>

<link name="lr_ffe">
<visual>
<origin xyz="0.50309616869699469444 -0.011172287142751494149 0.15999999999999989231" rpy="1.570796326794896558 5.0826844163181759162e-31 1.570796326794896558" />
<geometry>
<mesh filename="../meshs/lr_ffe.stl"/>
</geometry>
<material name="lr_ffe_material">
<color rgba="0.91764705882352937127 0.91764705882352937127 0.91764705882352937127 1.0"/>
</material>
</visual>
<!-- Shapes for lr_ffe -->
<inertial>
<origin xyz="-0.0010781713030051376379 0.02377071285724849381 -6.8000000000095761621e-05" rpy="0 0 0"/>
<mass value="0.099322280000000040534" />
<inertia ixx="7.622033243367977147e-05" ixy="-1.2169429363959850755e-05"  ixz="-2.7660647920346263361e-07" iyy="1.1575718442005015032e-05" iyz="-9.1667649289161780381e-07" izz="8.201492674814341347e-05" />
</inertial>
</link>

<link name="lr_faa">
<visual>
<origin xyz="0.16000000000000080824 0.50309616869699469444 -0.028672287142751599898" rpy="-1.570796326794896558 -1.570796326794896558 0" />
<geometry>
<mesh filename="../meshs/lr_faa.stl"/>
</geometry>
<material name="lr_faa_material">
<color rgba="0.91764705882352937127 0.91764705882352937127 0.91764705882352937127 1.0"/>
</material>
</visual>
<!-- Shapes for lr_faa -->
<collision>
<origin xyz="8.0491169285323849181e-16 -0.04290383130300534642 0.013327712857248402711" rpy="3.141592653589793116 -1.3962636194521678146 1.570796326794896558" />
<geometry>
<box size="0.16000000000000000333 0.055000000000000000278 0.01200000000000000025" />
</geometry>
</collision>
<!-- <collision>
<origin xyz="8.0491169285323849181e-16 9.6168696994691771351e-05 0.038827712857248404543" rpy="3.141592653589793116 -3.0814879110221995446e-31 1.570796326794896558" />
<geometry>
<cylinder length="0.06500000000000000222" radius="0.026999999999999999695" />
</geometry>
</collision> -->
<inertial>
<origin xyz="2.9000000000833914271e-05 -0.0163368313030051171 0.015338712857248394672" rpy="0 0 0"/>
<mass value="0.50700000000000011724" />
<inertia ixx="0.0010948634166535289088" ixy="-1.3506187775236006862e-06"  ixz="-3.5176485711190878634e-06" iyy="0.00091018596985867122537" iyz="-0.00019142590272031565803" izz="0.00044463279984352933449" />
</inertial>
</link>

<link name="LR_FOOT">
<inertial>
<origin xyz="0 0 0" rpy="0 0 0" />
<mass value="1e-9" />
<inertia ixx="0" ixy="0" ixz="0" iyy="0" iyz="0" izz="0" />
</inertial>
</link>
<joint name="LR_FOOT_frame" type="fixed">
<origin xyz="-2.7755575615628913511e-16 -0.048688979881310823217 0.014485028526582469088" rpy="-3.141592653589793116 -1.3962634015954653588 1.570796326794896558" />
<parent link="lr_faa" />
<child link="LR_FOOT" />
<axis xyz="0 0 0"/>
</joint>

<joint name="LR_FAA" type="revolute">
<origin xyz="7.771561172376095783e-16 0.017500000000000015543 -9.1593399531575414585e-16" rpy="-1.570796326794896336 -1.5707963267948850117 0" />
<parent link="lr_ffe" />
<child link="lr_faa" />
<axis xyz="0 0 1"/>
<limit effort="5" velocity="42" lower="-0.52359877559829881566" upper="0.52359877559829881566"/>
<joint_properties friction="0.0"/>
</joint>

<joint name="LR_FFE" type="revolute">
<origin xyz="-0.1800000000000017697 2.9490299091605720605e-17 -9.7144514654701197287e-16" rpy="-2.4605607242230561785e-15 -2.1937466413332281916e-15 -2.4980018054056664297e-16" />
<parent link="lr_kfe" />
<child link="lr_ffe" />
<axis xyz="0 0 1"/>
<limit effort="20" velocity="23" lower="-0.52359877559829881566" upper="0.69813170079773179122"/>
<joint_properties friction="0.0"/>
</joint>

<joint name="LR_KFE" type="revolute">
<origin xyz="-0.21999999999999853006 7.7264583620006987985e-15 -0.074199999999998419997" rpy="1.2766813666707529471e-14 1.7506442815481622092e-15 -4.7184478546574556665e-16" />
<parent link="lr_hfe" />
<child link="lr_kfe" />
<axis xyz="0 0 1"/>
<limit effort="30" velocity="14" lower="0" upper="2.0943951023931952626"/>
<joint_properties friction="0.0"/>
</joint>

<joint name="LR_HFE" type="revolute">
<origin xyz="-1.0130785099704553431e-15 -0.015799999999999869704 -0.064999999999998711586" rpy="-1.570796326794891673 -0.78539816339745049945 2.2818401626814027346e-14" />
<parent link="lr_haa" />
<child link="lr_hfe" />
<axis xyz="0 0 1"/>
<limit effort="30" velocity="20" lower="-1.7453292519943295336" upper="0.52359877559829881566"/>
<joint_properties friction="0.0"/>
</joint>

<joint name="LR_HAA" type="revolute">
<origin xyz="0.015799999999996469646 -2.9143354396410359186e-16 -0.064999999999999238942" rpy="-2.3800406090414426943e-15 -1.5707963267948694686 0" />
<parent link="lr_hr" />
<child link="lr_haa" />
<axis xyz="0 0 1"/>
<limit effort="20" velocity="23" lower="-0.61086523819801530344" upper="0.61086523819801530344"/>
<joint_properties friction="0.0"/>
</joint>

<joint name="LR_HR" type="revolute">
<origin xyz="1.1232681451645076202e-15 -0.070000000000000575651 1.4718781748967987512e-15" rpy="1.4130832128180086564e-15 0.7853981633974472798 -8.3266726844983662902e-17" />
<parent link="torso" />
<child link="lr_hr" />
<axis xyz="0 0 1"/>
<limit effort="20" velocity="23" lower="-0.61086523819801530344" upper="0.61086523819801530344"/>
<joint_properties friction="0.0"/>
</joint>


</robot>
